[2024-12-29T18:22:17.990+0000] {taskinstance.py:1979} INFO - Dependencies all met for dep_context=non-requeueable deps ti=<TaskInstance: postgres_jaffle_to_snowflake.airbyte_check_sync manual__2024-12-29T18:21:43.791402+00:00 [queued]>
[2024-12-29T18:22:18.038+0000] {taskinstance.py:1979} INFO - Dependencies all met for dep_context=requeueable deps ti=<TaskInstance: postgres_jaffle_to_snowflake.airbyte_check_sync manual__2024-12-29T18:21:43.791402+00:00 [queued]>
[2024-12-29T18:22:18.039+0000] {taskinstance.py:2193} INFO - Starting attempt 1 of 1
[2024-12-29T18:22:18.126+0000] {taskinstance.py:2217} INFO - Executing <Task(AirbyteJobSensor): airbyte_check_sync> on 2024-12-29 18:21:43.791402+00:00
[2024-12-29T18:22:18.211+0000] {standard_task_runner.py:60} INFO - Started process 335 to run task
[2024-12-29T18:22:18.295+0000] {standard_task_runner.py:87} INFO - Running: ['***', 'tasks', 'run', 'postgres_jaffle_to_snowflake', 'airbyte_check_sync', 'manual__2024-12-29T18:21:43.791402+00:00', '--job-id', '103', '--raw', '--subdir', 'DAGS_FOLDER/postgres_jaffle_to_snowflake.py', '--cfg-path', '/tmp/tmpyr_pclkw']
[2024-12-29T18:22:18.341+0000] {standard_task_runner.py:88} INFO - Job 103: Subtask airbyte_check_sync
[2024-12-29T18:22:19.066+0000] {task_command.py:423} INFO - Running <TaskInstance: postgres_jaffle_to_snowflake.airbyte_check_sync manual__2024-12-29T18:21:43.791402+00:00 [running]> on host a68ea757822e
[2024-12-29T18:22:20.963+0000] {taskinstance.py:2513} INFO - Exporting env vars: AIRFLOW_CTX_DAG_OWNER='***' AIRFLOW_CTX_DAG_ID='postgres_jaffle_to_snowflake' AIRFLOW_CTX_TASK_ID='airbyte_check_sync' AIRFLOW_CTX_EXECUTION_DATE='2024-12-29T18:21:43.791402+00:00' AIRFLOW_CTX_TRY_NUMBER='1' AIRFLOW_CTX_DAG_RUN_ID='manual__2024-12-29T18:21:43.791402+00:00'
[2024-12-29T18:22:21.040+0000] {base.py:83} INFO - Using connection ID 'airbyte_conn' for task execution.
[2024-12-29T18:22:21.175+0000] {airbyte.py:104} INFO - Waiting for job 65 to complete.
[2024-12-29T18:23:21.335+0000] {base.py:83} INFO - Using connection ID 'airbyte_conn' for task execution.
[2024-12-29T18:23:21.525+0000] {airbyte.py:104} INFO - Waiting for job 65 to complete.
[2024-12-29T18:24:21.620+0000] {base.py:83} INFO - Using connection ID 'airbyte_conn' for task execution.
[2024-12-29T18:24:21.679+0000] {airbyte.py:104} INFO - Waiting for job 65 to complete.
[2024-12-29T18:25:21.774+0000] {base.py:83} INFO - Using connection ID 'airbyte_conn' for task execution.
[2024-12-29T18:25:21.882+0000] {airbyte.py:104} INFO - Waiting for job 65 to complete.
[2024-12-29T18:27:02.780+0000] {base.py:83} INFO - Using connection ID 'airbyte_conn' for task execution.
[2024-12-29T18:27:03.344+0000] {airbyte.py:104} INFO - Waiting for job 65 to complete.
[2024-12-29T18:28:04.261+0000] {base.py:83} INFO - Using connection ID 'airbyte_conn' for task execution.
[2024-12-29T18:28:04.306+0000] {airbyte.py:104} INFO - Waiting for job 65 to complete.
[2024-12-29T18:29:04.553+0000] {base.py:83} INFO - Using connection ID 'airbyte_conn' for task execution.
[2024-12-29T18:29:04.709+0000] {airbyte.py:104} INFO - Waiting for job 65 to complete.
[2024-12-29T18:30:04.843+0000] {base.py:83} INFO - Using connection ID 'airbyte_conn' for task execution.
[2024-12-29T18:30:05.177+0000] {airbyte.py:104} INFO - Waiting for job 65 to complete.
[2024-12-29T18:31:04.040+0000] {base.py:83} INFO - Using connection ID 'airbyte_conn' for task execution.
[2024-12-29T18:31:16.747+0000] {http.py:242} WARNING - HTTPConnectionPool(host='host.docker.internal', port=8001): Max retries exceeded with url: /api/v1/jobs/get (Caused by NewConnectionError('<urllib3.connection.HTTPConnection object at 0x7fa86349e3b0>: Failed to establish a new connection: [Errno -3] Temporary failure in name resolution')) Tenacity will retry to execute the operation
[2024-12-29T18:31:50.066+0000] {taskinstance.py:2731} ERROR - Task failed with exception
Traceback (most recent call last):
  File "/home/airflow/.local/lib/python3.10/site-packages/urllib3/connection.py", line 174, in _new_conn
    conn = connection.create_connection(
  File "/home/airflow/.local/lib/python3.10/site-packages/urllib3/util/connection.py", line 72, in create_connection
    for res in socket.getaddrinfo(host, port, family, socket.SOCK_STREAM):
  File "/usr/local/lib/python3.10/socket.py", line 955, in getaddrinfo
    for res in _socket.getaddrinfo(host, port, family, type, proto, flags):
socket.gaierror: [Errno -3] Temporary failure in name resolution

During handling of the above exception, another exception occurred:

Traceback (most recent call last):
  File "/home/airflow/.local/lib/python3.10/site-packages/urllib3/connectionpool.py", line 715, in urlopen
    httplib_response = self._make_request(
  File "/home/airflow/.local/lib/python3.10/site-packages/urllib3/connectionpool.py", line 416, in _make_request
    conn.request(method, url, **httplib_request_kw)
  File "/home/airflow/.local/lib/python3.10/site-packages/urllib3/connection.py", line 244, in request
    super(HTTPConnection, self).request(method, url, body=body, headers=headers)
  File "/usr/local/lib/python3.10/http/client.py", line 1283, in request
    self._send_request(method, url, body, headers, encode_chunked)
  File "/usr/local/lib/python3.10/http/client.py", line 1329, in _send_request
    self.endheaders(body, encode_chunked=encode_chunked)
  File "/usr/local/lib/python3.10/http/client.py", line 1278, in endheaders
    self._send_output(message_body, encode_chunked=encode_chunked)
  File "/usr/local/lib/python3.10/http/client.py", line 1038, in _send_output
    self.send(msg)
  File "/usr/local/lib/python3.10/http/client.py", line 976, in send
    self.connect()
  File "/home/airflow/.local/lib/python3.10/site-packages/urllib3/connection.py", line 205, in connect
    conn = self._new_conn()
  File "/home/airflow/.local/lib/python3.10/site-packages/urllib3/connection.py", line 186, in _new_conn
    raise NewConnectionError(
urllib3.exceptions.NewConnectionError: <urllib3.connection.HTTPConnection object at 0x7fa86349e3b0>: Failed to establish a new connection: [Errno -3] Temporary failure in name resolution

During handling of the above exception, another exception occurred:

Traceback (most recent call last):
  File "/home/airflow/.local/lib/python3.10/site-packages/requests/adapters.py", line 486, in send
    resp = conn.urlopen(
  File "/home/airflow/.local/lib/python3.10/site-packages/urllib3/connectionpool.py", line 799, in urlopen
    retries = retries.increment(
  File "/home/airflow/.local/lib/python3.10/site-packages/urllib3/util/retry.py", line 592, in increment
    raise MaxRetryError(_pool, url, error or ResponseError(cause))
urllib3.exceptions.MaxRetryError: HTTPConnectionPool(host='host.docker.internal', port=8001): Max retries exceeded with url: /api/v1/jobs/get (Caused by NewConnectionError('<urllib3.connection.HTTPConnection object at 0x7fa86349e3b0>: Failed to establish a new connection: [Errno -3] Temporary failure in name resolution'))

During handling of the above exception, another exception occurred:

Traceback (most recent call last):
  File "/home/airflow/.local/lib/python3.10/site-packages/airflow/models/taskinstance.py", line 444, in _execute_task
    result = _execute_callable(context=context, **execute_callable_kwargs)
  File "/home/airflow/.local/lib/python3.10/site-packages/airflow/models/taskinstance.py", line 414, in _execute_callable
    return execute_callable(context=context, **execute_callable_kwargs)
  File "/home/airflow/.local/lib/python3.10/site-packages/airflow/providers/airbyte/sensors/airbyte.py", line 110, in execute
    super().execute(context)
  File "/home/airflow/.local/lib/python3.10/site-packages/airflow/sensors/base.py", line 265, in execute
    raise e
  File "/home/airflow/.local/lib/python3.10/site-packages/airflow/sensors/base.py", line 247, in execute
    poke_return = self.poke(context)
  File "/home/airflow/.local/lib/python3.10/site-packages/airflow/providers/airbyte/sensors/airbyte.py", line 83, in poke
    job = hook.get_job(job_id=self.airbyte_job_id)
  File "/home/airflow/.local/lib/python3.10/site-packages/airflow/providers/airbyte/hooks/airbyte.py", line 161, in get_job
    return self.run(
  File "/home/airflow/.local/lib/python3.10/site-packages/airflow/providers/http/hooks/http.py", line 187, in run
    return self.run_and_check(session, prepped_request, extra_options)
  File "/home/airflow/.local/lib/python3.10/site-packages/airflow/providers/http/hooks/http.py", line 243, in run_and_check
    raise ex
  File "/home/airflow/.local/lib/python3.10/site-packages/airflow/providers/http/hooks/http.py", line 235, in run_and_check
    response = session.send(prepped_request, **send_kwargs)
  File "/home/airflow/.local/lib/python3.10/site-packages/requests/sessions.py", line 703, in send
    r = adapter.send(request, **kwargs)
  File "/home/airflow/.local/lib/python3.10/site-packages/requests/adapters.py", line 519, in send
    raise ConnectionError(e, request=request)
requests.exceptions.ConnectionError: HTTPConnectionPool(host='host.docker.internal', port=8001): Max retries exceeded with url: /api/v1/jobs/get (Caused by NewConnectionError('<urllib3.connection.HTTPConnection object at 0x7fa86349e3b0>: Failed to establish a new connection: [Errno -3] Temporary failure in name resolution'))
[2024-12-29T18:32:13.172+0000] {taskinstance.py:1149} INFO - Marking task as FAILED. dag_id=postgres_jaffle_to_snowflake, task_id=airbyte_check_sync, execution_date=20241229T182143, start_date=20241229T182217, end_date=20241229T183212
[2024-12-29T18:32:14.408+0000] {standard_task_runner.py:107} ERROR - Failed to execute job 103 for task airbyte_check_sync (HTTPConnectionPool(host='host.docker.internal', port=8001): Max retries exceeded with url: /api/v1/jobs/get (Caused by NewConnectionError('<urllib3.connection.HTTPConnection object at 0x7fa86349e3b0>: Failed to establish a new connection: [Errno -3] Temporary failure in name resolution')); 335)
[2024-12-29T18:32:15.228+0000] {local_task_job_runner.py:234} INFO - Task exited with return code 1
[2024-12-29T18:32:17.226+0000] {taskinstance.py:3312} INFO - 0 downstream tasks scheduled from follow-on schedule check
