[2024-12-28T13:40:32.413+0000] {taskinstance.py:1979} INFO - Dependencies all met for dep_context=non-requeueable deps ti=<TaskInstance: postgres_jaffle_to_snowflake.airbyte_trigger_sync manual__2024-12-28T13:40:07.101518+00:00 [queued]>
[2024-12-28T13:40:32.481+0000] {taskinstance.py:1979} INFO - Dependencies all met for dep_context=requeueable deps ti=<TaskInstance: postgres_jaffle_to_snowflake.airbyte_trigger_sync manual__2024-12-28T13:40:07.101518+00:00 [queued]>
[2024-12-28T13:40:32.485+0000] {taskinstance.py:2193} INFO - Starting attempt 1 of 1
[2024-12-28T13:40:32.572+0000] {taskinstance.py:2217} INFO - Executing <Task(AirbyteTriggerSyncOperator): airbyte_trigger_sync> on 2024-12-28 13:40:07.101518+00:00
[2024-12-28T13:40:32.626+0000] {standard_task_runner.py:60} INFO - Started process 534 to run task
[2024-12-28T13:40:32.640+0000] {standard_task_runner.py:87} INFO - Running: ['***', 'tasks', 'run', 'postgres_jaffle_to_snowflake', 'airbyte_trigger_sync', 'manual__2024-12-28T13:40:07.101518+00:00', '--job-id', '73', '--raw', '--subdir', 'DAGS_FOLDER/postgres_jaffle_to_snowflake.py', '--cfg-path', '/tmp/tmpcrgrzzhe']
[2024-12-28T13:40:32.657+0000] {standard_task_runner.py:88} INFO - Job 73: Subtask airbyte_trigger_sync
[2024-12-28T13:40:32.936+0000] {task_command.py:423} INFO - Running <TaskInstance: postgres_jaffle_to_snowflake.airbyte_trigger_sync manual__2024-12-28T13:40:07.101518+00:00 [running]> on host a68ea757822e
[2024-12-28T13:40:33.244+0000] {taskinstance.py:2513} INFO - Exporting env vars: AIRFLOW_CTX_DAG_OWNER='***' AIRFLOW_CTX_DAG_ID='postgres_jaffle_to_snowflake' AIRFLOW_CTX_TASK_ID='airbyte_trigger_sync' AIRFLOW_CTX_EXECUTION_DATE='2024-12-28T13:40:07.101518+00:00' AIRFLOW_CTX_TRY_NUMBER='1' AIRFLOW_CTX_DAG_RUN_ID='manual__2024-12-28T13:40:07.101518+00:00'
[2024-12-28T13:40:33.288+0000] {base.py:83} INFO - Using connection ID 'airbyte_conn' for task execution.
[2024-12-28T13:40:37.881+0000] {http.py:199} ERROR - HTTP error: Conflict
[2024-12-28T13:40:37.897+0000] {http.py:200} ERROR - {"message":"A sync is already running for: 69e2db52-dcc2-4e64-8d18-47942cd5a669","exceptionClassName":"io.airbyte.commons.server.errors.ValueConflictKnownException","exceptionStack":["io.airbyte.commons.server.errors.ValueConflictKnownException: A sync is already running for: 69e2db52-dcc2-4e64-8d18-47942cd5a669","\tat io.airbyte.commons.server.handlers.SchedulerHandler.readJobFromResult(SchedulerHandler.java:820)","\tat io.airbyte.commons.server.handlers.SchedulerHandler.submitManualSyncToWorker(SchedulerHandler.java:790)","\tat io.airbyte.commons.server.handlers.SchedulerHandler.syncConnection(SchedulerHandler.java:572)","\tat io.airbyte.server.apis.ConnectionApiController.lambda$syncConnection$16(ConnectionApiController.java:247)","\tat io.airbyte.server.apis.ApiHelper.execute(ApiHelper.java:28)","\tat io.airbyte.server.apis.ConnectionApiController.syncConnection(ConnectionApiController.java:247)","\tat io.airbyte.server.apis.$ConnectionApiController$Definition$Exec.dispatch(Unknown Source)","\tat io.micronaut.context.AbstractExecutableMethodsDefinition$DispatchedExecutableMethod.invokeUnsafe(AbstractExecutableMethodsDefinition.java:461)","\tat io.micronaut.context.DefaultBeanContext$BeanContextUnsafeExecutionHandle.invokeUnsafe(DefaultBeanContext.java:4276)","\tat io.micronaut.web.router.AbstractRouteMatch.execute(AbstractRouteMatch.java:271)","\tat io.micronaut.http.server.RouteExecutor.executeRouteAndConvertBody(RouteExecutor.java:488)","\tat io.micronaut.http.server.RouteExecutor.lambda$callRoute$6(RouteExecutor.java:465)","\tat io.micronaut.core.execution.ExecutionFlow.lambda$async$1(ExecutionFlow.java:87)","\tat io.micronaut.core.propagation.PropagatedContext.lambda$wrap$3(PropagatedContext.java:211)","\tat java.base/java.util.concurrent.ThreadPoolExecutor.runWorker(ThreadPoolExecutor.java:1144)","\tat java.base/java.util.concurrent.ThreadPoolExecutor$Worker.run(ThreadPoolExecutor.java:642)","\tat java.base/java.lang.Thread.run(Thread.java:1583)"]}
[2024-12-28T13:40:38.234+0000] {taskinstance.py:2731} ERROR - Task failed with exception
Traceback (most recent call last):
  File "/home/airflow/.local/lib/python3.10/site-packages/airflow/providers/http/hooks/http.py", line 197, in check_response
    response.raise_for_status()
  File "/home/airflow/.local/lib/python3.10/site-packages/requests/models.py", line 1021, in raise_for_status
    raise HTTPError(http_error_msg, response=self)
requests.exceptions.HTTPError: 409 Client Error: Conflict for url: http://host.docker.internal:8001/api/v1/connections/sync

During handling of the above exception, another exception occurred:

Traceback (most recent call last):
  File "/home/airflow/.local/lib/python3.10/site-packages/airflow/models/taskinstance.py", line 444, in _execute_task
    result = _execute_callable(context=context, **execute_callable_kwargs)
  File "/home/airflow/.local/lib/python3.10/site-packages/airflow/models/taskinstance.py", line 414, in _execute_callable
    return execute_callable(context=context, **execute_callable_kwargs)
  File "/home/airflow/.local/lib/python3.10/site-packages/airflow/providers/airbyte/operators/airbyte.py", line 81, in execute
    job_object = hook.submit_sync_connection(connection_id=self.connection_id)
  File "/home/airflow/.local/lib/python3.10/site-packages/airflow/providers/airbyte/hooks/airbyte.py", line 149, in submit_sync_connection
    return self.run(
  File "/home/airflow/.local/lib/python3.10/site-packages/airflow/providers/http/hooks/http.py", line 187, in run
    return self.run_and_check(session, prepped_request, extra_options)
  File "/home/airflow/.local/lib/python3.10/site-packages/airflow/providers/http/hooks/http.py", line 238, in run_and_check
    self.check_response(response)
  File "/home/airflow/.local/lib/python3.10/site-packages/airflow/providers/http/hooks/http.py", line 201, in check_response
    raise AirflowException(str(response.status_code) + ":" + response.reason)
airflow.exceptions.AirflowException: 409:Conflict
[2024-12-28T13:40:38.409+0000] {taskinstance.py:1149} INFO - Marking task as FAILED. dag_id=postgres_jaffle_to_snowflake, task_id=airbyte_trigger_sync, execution_date=20241228T134007, start_date=20241228T134032, end_date=20241228T134038
[2024-12-28T13:40:38.558+0000] {standard_task_runner.py:107} ERROR - Failed to execute job 73 for task airbyte_trigger_sync (409:Conflict; 534)
[2024-12-28T13:40:38.619+0000] {local_task_job_runner.py:234} INFO - Task exited with return code 1
[2024-12-28T13:40:39.092+0000] {taskinstance.py:3312} INFO - 0 downstream tasks scheduled from follow-on schedule check
