[2024-12-28T13:25:35.995+0000] {taskinstance.py:1979} INFO - Dependencies all met for dep_context=non-requeueable deps ti=<TaskInstance: postgres_jaffle_to_snowflake.airbyte_trigger_sync manual__2024-12-28T13:25:20.406127+00:00 [queued]>
[2024-12-28T13:25:36.009+0000] {taskinstance.py:1979} INFO - Dependencies all met for dep_context=requeueable deps ti=<TaskInstance: postgres_jaffle_to_snowflake.airbyte_trigger_sync manual__2024-12-28T13:25:20.406127+00:00 [queued]>
[2024-12-28T13:25:36.010+0000] {taskinstance.py:2193} INFO - Starting attempt 1 of 1
[2024-12-28T13:25:36.033+0000] {taskinstance.py:2217} INFO - Executing <Task(AirbyteTriggerSyncOperator): airbyte_trigger_sync> on 2024-12-28 13:25:20.406127+00:00
[2024-12-28T13:25:36.047+0000] {standard_task_runner.py:60} INFO - Started process 329 to run task
[2024-12-28T13:25:36.054+0000] {standard_task_runner.py:87} INFO - Running: ['***', 'tasks', 'run', 'postgres_jaffle_to_snowflake', 'airbyte_trigger_sync', 'manual__2024-12-28T13:25:20.406127+00:00', '--job-id', '68', '--raw', '--subdir', 'DAGS_FOLDER/postgres_jaffle_to_snowflake.py', '--cfg-path', '/tmp/tmp4vrl01aq']
[2024-12-28T13:25:36.058+0000] {standard_task_runner.py:88} INFO - Job 68: Subtask airbyte_trigger_sync
[2024-12-28T13:25:36.198+0000] {task_command.py:423} INFO - Running <TaskInstance: postgres_jaffle_to_snowflake.airbyte_trigger_sync manual__2024-12-28T13:25:20.406127+00:00 [running]> on host a68ea757822e
[2024-12-28T13:25:36.350+0000] {taskinstance.py:2513} INFO - Exporting env vars: AIRFLOW_CTX_DAG_OWNER='***' AIRFLOW_CTX_DAG_ID='postgres_jaffle_to_snowflake' AIRFLOW_CTX_TASK_ID='airbyte_trigger_sync' AIRFLOW_CTX_EXECUTION_DATE='2024-12-28T13:25:20.406127+00:00' AIRFLOW_CTX_TRY_NUMBER='1' AIRFLOW_CTX_DAG_RUN_ID='manual__2024-12-28T13:25:20.406127+00:00'
[2024-12-28T13:25:36.381+0000] {base.py:83} INFO - Using connection ID 'airbyte_conn' for task execution.
[2024-12-28T13:25:41.631+0000] {http.py:199} ERROR - HTTP error: Not Found
[2024-12-28T13:25:41.632+0000] {http.py:200} ERROR - {"type":"about:blank","status":404}
[2024-12-28T13:25:41.646+0000] {taskinstance.py:2731} ERROR - Task failed with exception
Traceback (most recent call last):
  File "/home/airflow/.local/lib/python3.10/site-packages/airflow/providers/http/hooks/http.py", line 197, in check_response
    response.raise_for_status()
  File "/home/airflow/.local/lib/python3.10/site-packages/requests/models.py", line 1021, in raise_for_status
    raise HTTPError(http_error_msg, response=self)
requests.exceptions.HTTPError: 404 Client Error: Not Found for url: http://host.docker.internal:8006/api/v1/connections/sync

During handling of the above exception, another exception occurred:

Traceback (most recent call last):
  File "/home/airflow/.local/lib/python3.10/site-packages/airflow/models/taskinstance.py", line 444, in _execute_task
    result = _execute_callable(context=context, **execute_callable_kwargs)
  File "/home/airflow/.local/lib/python3.10/site-packages/airflow/models/taskinstance.py", line 414, in _execute_callable
    return execute_callable(context=context, **execute_callable_kwargs)
  File "/home/airflow/.local/lib/python3.10/site-packages/airflow/providers/airbyte/operators/airbyte.py", line 81, in execute
    job_object = hook.submit_sync_connection(connection_id=self.connection_id)
  File "/home/airflow/.local/lib/python3.10/site-packages/airflow/providers/airbyte/hooks/airbyte.py", line 149, in submit_sync_connection
    return self.run(
  File "/home/airflow/.local/lib/python3.10/site-packages/airflow/providers/http/hooks/http.py", line 187, in run
    return self.run_and_check(session, prepped_request, extra_options)
  File "/home/airflow/.local/lib/python3.10/site-packages/airflow/providers/http/hooks/http.py", line 238, in run_and_check
    self.check_response(response)
  File "/home/airflow/.local/lib/python3.10/site-packages/airflow/providers/http/hooks/http.py", line 201, in check_response
    raise AirflowException(str(response.status_code) + ":" + response.reason)
airflow.exceptions.AirflowException: 404:Not Found
[2024-12-28T13:25:41.658+0000] {taskinstance.py:1149} INFO - Marking task as FAILED. dag_id=postgres_jaffle_to_snowflake, task_id=airbyte_trigger_sync, execution_date=20241228T132520, start_date=20241228T132535, end_date=20241228T132541
[2024-12-28T13:25:41.702+0000] {standard_task_runner.py:107} ERROR - Failed to execute job 68 for task airbyte_trigger_sync (404:Not Found; 329)
[2024-12-28T13:25:41.719+0000] {local_task_job_runner.py:234} INFO - Task exited with return code 1
[2024-12-28T13:25:41.753+0000] {taskinstance.py:3312} INFO - 0 downstream tasks scheduled from follow-on schedule check
